Start Synthesizing Wav File
SLURM_SUBMIT_DIR = /home/lapis/UGRP/tts/Tacotron2-Wavenet-Korean-TTS
CUDA_HOME = /opt/ohpc/pub/apps/cuda-10.0
CUDA_VISIBLE_DEVICES = 0,2
CUDA_VERSION=10.0
0: n8
0: /home/lapis/UGRP/tts/Tacotron2-Wavenet-Korean-TTS
0: Sat Sep 12 15:20:12 KST 2020
WARNING:tensorflow:
The TensorFlow contrib module will not be included in TensorFlow 2.0.
For more information, please see:
  * https://github.com/tensorflow/community/blob/master/rfcs/20180907-contrib-sunset.md
  * https://github.com/tensorflow/addons
  * https://github.com/tensorflow/io (for I/O related ops)
If you depend on functionality not listed there, please file an issue.

WARNING:tensorflow:From synthesizer.py:37: The name tf.logging.set_verbosity is deprecated. Please use tf.compat.v1.logging.set_verbosity instead.

WARNING:tensorflow:From synthesizer.py:37: The name tf.logging.ERROR is deprecated. Please use tf.compat.v1.logging.ERROR instead.

2020-09-12 15:21:18.981605: I tensorflow/core/platform/cpu_feature_guard.cc:142] Your CPU supports instructions that this TensorFlow binary was not compiled to use: AVX2 FMA
2020-09-12 15:21:18.985573: I tensorflow/core/platform/profile_utils/cpu_utils.cc:94] CPU Frequency: 3598000000 Hz
2020-09-12 15:21:18.985714: I tensorflow/compiler/xla/service/service.cc:168] XLA service 0x556f12d14650 initialized for platform Host (this does not guarantee that XLA will be used). Devices:
2020-09-12 15:21:18.985729: I tensorflow/compiler/xla/service/service.cc:176]   StreamExecutor device (0): Host, Default Version
2020-09-12 15:21:20.417943: W tensorflow/core/framework/op_kernel.cc:1651] OP_REQUIRES failed at save_restore_v2_ops.cc:184 : Out of range: Read less bytes than requested
 [*] Found lastest checkpoint: logs_tacotron2/train_sample/model.ckpt-492000
Constructing model: tacotron
UPDATE attention_kernel: (31,) -> [31]
UPDATE postnet_kernel_size: (5,) -> [5]
========================================
 model_type: single
========================================
Initialized Tacotron model. Dimensions: 
    embedding:                512
    encoder conv out:               512
    encoder out:              512
    attention out:            1024
    decoder prenet lstm concat out :        1536
    decoder cell out:         162
    decoder out (2 frames):  162
    decoder mel out:    80
    mel out:    80
    postnet out:              256
    linear out:               1025
  Tacotron Parameters       29.142 Million.
Loading checkpoint: logs_tacotron2/train_sample/model.ckpt-492000
Traceback (most recent call last):
  File "/home/lapis/.local/lib/python3.6/site-packages/tensorflow_core/python/client/session.py", line 1365, in _do_call
    return fn(*args)
  File "/home/lapis/.local/lib/python3.6/site-packages/tensorflow_core/python/client/session.py", line 1350, in _run_fn
    target_list, run_metadata)
  File "/home/lapis/.local/lib/python3.6/site-packages/tensorflow_core/python/client/session.py", line 1443, in _call_tf_sessionrun
    run_metadata)
tensorflow.python.framework.errors_impl.OutOfRangeError: Read less bytes than requested
	 [[{{node save/RestoreV2}}]]

During handling of the above exception, another exception occurred:

Traceback (most recent call last):
  File "synthesizer.py", line 342, in <module>
    synthesizer.load(config.load_path, config.num_speakers, config.checkpoint_step,inference_prenet_dropout=False)
  File "synthesizer.py", line 81, in load
    saver.restore(self.sess, checkpoint_path)
  File "/home/lapis/.local/lib/python3.6/site-packages/tensorflow_core/python/training/saver.py", line 1290, in restore
    {self.saver_def.filename_tensor_name: save_path})
  File "/home/lapis/.local/lib/python3.6/site-packages/tensorflow_core/python/client/session.py", line 956, in run
    run_metadata_ptr)
  File "/home/lapis/.local/lib/python3.6/site-packages/tensorflow_core/python/client/session.py", line 1180, in _run
    feed_dict_tensor, options, run_metadata)
  File "/home/lapis/.local/lib/python3.6/site-packages/tensorflow_core/python/client/session.py", line 1359, in _do_run
    run_metadata)
  File "/home/lapis/.local/lib/python3.6/site-packages/tensorflow_core/python/client/session.py", line 1384, in _do_call
    raise type(e)(node_def, op, message)
tensorflow.python.framework.errors_impl.OutOfRangeError: Read less bytes than requested
	 [[node save/RestoreV2 (defined at /home/lapis/.local/lib/python3.6/site-packages/tensorflow_core/python/framework/ops.py:1748) ]]

Original stack trace for 'save/RestoreV2':
  File "synthesizer.py", line 342, in <module>
    synthesizer.load(config.load_path, config.num_speakers, config.checkpoint_step,inference_prenet_dropout=False)
  File "synthesizer.py", line 80, in load
    saver = tf.train.Saver()
  File "/home/lapis/.local/lib/python3.6/site-packages/tensorflow_core/python/training/saver.py", line 828, in __init__
    self.build()
  File "/home/lapis/.local/lib/python3.6/site-packages/tensorflow_core/python/training/saver.py", line 840, in build
    self._build(self._filename, build_save=True, build_restore=True)
  File "/home/lapis/.local/lib/python3.6/site-packages/tensorflow_core/python/training/saver.py", line 878, in _build
    build_restore=build_restore)
  File "/home/lapis/.local/lib/python3.6/site-packages/tensorflow_core/python/training/saver.py", line 508, in _build_internal
    restore_sequentially, reshape)
  File "/home/lapis/.local/lib/python3.6/site-packages/tensorflow_core/python/training/saver.py", line 328, in _AddRestoreOps
    restore_sequentially)
  File "/home/lapis/.local/lib/python3.6/site-packages/tensorflow_core/python/training/saver.py", line 575, in bulk_restore
    return io_ops.restore_v2(filename_tensor, names, slices, dtypes)
  File "/home/lapis/.local/lib/python3.6/site-packages/tensorflow_core/python/ops/gen_io_ops.py", line 1696, in restore_v2
    name=name)
  File "/home/lapis/.local/lib/python3.6/site-packages/tensorflow_core/python/framework/op_def_library.py", line 794, in _apply_op_helper
    op_def=op_def)
  File "/home/lapis/.local/lib/python3.6/site-packages/tensorflow_core/python/util/deprecation.py", line 507, in new_func
    return func(*args, **kwargs)
  File "/home/lapis/.local/lib/python3.6/site-packages/tensorflow_core/python/framework/ops.py", line 3357, in create_op
    attrs, op_def, compute_device)
  File "/home/lapis/.local/lib/python3.6/site-packages/tensorflow_core/python/framework/ops.py", line 3426, in _create_op_internal
    op_def=op_def)
  File "/home/lapis/.local/lib/python3.6/site-packages/tensorflow_core/python/framework/ops.py", line 1748, in __init__
    self._traceback = tf_stack.extract_stack()

Sat Sep 12 15:21:21 KST 2020
             JOBID PARTITION     NAME     USER ST       TIME  NODES NODELIST(REASON)
             29505   gpu-all KTacoSyn    lapis  R       1:09      1 n8
##### END #####
